[2022-09-05 14:34:06,624] {taskinstance.py:1179} INFO - Dependencies all met for <TaskInstance: create_tables.check_file scheduled__2022-09-01T00:00:00+00:00 [queued]>
[2022-09-05 14:34:06,779] {taskinstance.py:1179} INFO - Dependencies all met for <TaskInstance: create_tables.check_file scheduled__2022-09-01T00:00:00+00:00 [queued]>
[2022-09-05 14:34:06,781] {taskinstance.py:1376} INFO - 
--------------------------------------------------------------------------------
[2022-09-05 14:34:06,782] {taskinstance.py:1377} INFO - Starting attempt 25 of 27
[2022-09-05 14:34:06,792] {taskinstance.py:1378} INFO - 
--------------------------------------------------------------------------------
[2022-09-05 14:34:07,200] {taskinstance.py:1397} INFO - Executing <Task(BashOperator): check_file> on 2022-09-01 00:00:00+00:00
[2022-09-05 14:34:07,278] {standard_task_runner.py:52} INFO - Started process 1216 to run task
[2022-09-05 14:34:08,551] {standard_task_runner.py:79} INFO - Running: ['***', 'tasks', 'run', 'create_tables', 'check_file', 'scheduled__2022-09-01T00:00:00+00:00', '--job-id', '132', '--raw', '--subdir', 'DAGS_FOLDER/create.py', '--cfg-path', '/tmp/tmpc16mlw8h', '--error-file', '/tmp/tmp8e00_xej']
[2022-09-05 14:34:08,553] {standard_task_runner.py:80} INFO - Job 132: Subtask check_file
[2022-09-05 14:34:28,936] {task_command.py:371} INFO - Running <TaskInstance: create_tables.check_file scheduled__2022-09-01T00:00:00+00:00 [running]> on host cdeef4137858
[2022-09-05 14:34:30,839] {taskinstance.py:1591} INFO - Exporting the following env vars:
AIRFLOW_CTX_DAG_OWNER=***
AIRFLOW_CTX_DAG_ID=create_tables
AIRFLOW_CTX_TASK_ID=check_file
AIRFLOW_CTX_EXECUTION_DATE=2022-09-01T00:00:00+00:00
AIRFLOW_CTX_TRY_NUMBER=25
AIRFLOW_CTX_DAG_RUN_ID=scheduled__2022-09-01T00:00:00+00:00
[2022-09-05 14:34:30,860] {subprocess.py:62} INFO - Tmp dir root location: 
 /tmp
[2022-09-05 14:34:30,872] {subprocess.py:74} INFO - Running command: ['bash', '-c', '/var/lib/mysql-files/data/20181024_d1_0830_0900.csv']
[2022-09-05 14:34:30,929] {subprocess.py:85} INFO - Output:
[2022-09-05 14:34:31,500] {subprocess.py:92} INFO - bash: line 1: /var/lib/mysql-files/data/20181024_d1_0830_0900.csv: No such file or directory
[2022-09-05 14:34:31,501] {subprocess.py:96} INFO - Command exited with return code 127
[2022-09-05 14:34:33,565] {taskinstance.py:1909} ERROR - Task failed with exception
Traceback (most recent call last):
  File "/home/airflow/.local/lib/python3.7/site-packages/airflow/operators/bash.py", line 195, in execute
    f'Bash command failed. The command returned a non-zero exit code {result.exit_code}.'
airflow.exceptions.AirflowException: Bash command failed. The command returned a non-zero exit code 127.
[2022-09-05 14:34:34,340] {taskinstance.py:1420} INFO - Marking task as UP_FOR_RETRY. dag_id=create_tables, task_id=check_file, execution_date=20220901T000000, start_date=20220905T143406, end_date=20220905T143433
[2022-09-05 14:34:37,659] {standard_task_runner.py:97} ERROR - Failed to execute job 132 for task check_file (Bash command failed. The command returned a non-zero exit code 127.; 1216)
[2022-09-05 14:34:37,748] {local_task_job.py:156} INFO - Task exited with return code 1
[2022-09-05 14:34:38,888] {local_task_job.py:273} INFO - 0 downstream tasks scheduled from follow-on schedule check
