[2022-09-05 10:08:17,756] {taskinstance.py:1179} INFO - Dependencies all met for <TaskInstance: create_tables.check_file scheduled__2022-09-01T00:00:00+00:00 [queued]>
[2022-09-05 10:08:17,781] {taskinstance.py:1179} INFO - Dependencies all met for <TaskInstance: create_tables.check_file scheduled__2022-09-01T00:00:00+00:00 [queued]>
[2022-09-05 10:08:17,781] {taskinstance.py:1376} INFO - 
--------------------------------------------------------------------------------
[2022-09-05 10:08:17,782] {taskinstance.py:1377} INFO - Starting attempt 15 of 15
[2022-09-05 10:08:17,782] {taskinstance.py:1378} INFO - 
--------------------------------------------------------------------------------
[2022-09-05 10:08:17,873] {taskinstance.py:1397} INFO - Executing <Task(BashOperator): check_file> on 2022-09-01 00:00:00+00:00
[2022-09-05 10:08:17,879] {standard_task_runner.py:52} INFO - Started process 739 to run task
[2022-09-05 10:08:17,884] {standard_task_runner.py:79} INFO - Running: ['***', 'tasks', 'run', 'create_tables', 'check_file', 'scheduled__2022-09-01T00:00:00+00:00', '--job-id', '84', '--raw', '--subdir', 'DAGS_FOLDER/create.py', '--cfg-path', '/tmp/tmpg_xkfi5p', '--error-file', '/tmp/tmptqe0ispp']
[2022-09-05 10:08:17,886] {standard_task_runner.py:80} INFO - Job 84: Subtask check_file
[2022-09-05 10:08:18,038] {task_command.py:371} INFO - Running <TaskInstance: create_tables.check_file scheduled__2022-09-01T00:00:00+00:00 [running]> on host 613319c2eb0f
[2022-09-05 10:08:18,202] {taskinstance.py:1591} INFO - Exporting the following env vars:
AIRFLOW_CTX_DAG_OWNER=***
AIRFLOW_CTX_DAG_ID=create_tables
AIRFLOW_CTX_TASK_ID=check_file
AIRFLOW_CTX_EXECUTION_DATE=2022-09-01T00:00:00+00:00
AIRFLOW_CTX_TRY_NUMBER=15
AIRFLOW_CTX_DAG_RUN_ID=scheduled__2022-09-01T00:00:00+00:00
[2022-09-05 10:08:18,204] {subprocess.py:62} INFO - Tmp dir root location: 
 /tmp
[2022-09-05 10:08:18,205] {subprocess.py:74} INFO - Running command: ['bash', '-c', '/var/lib/mysql-files/data/20181024_d1_0830_0900.csv']
[2022-09-05 10:08:18,220] {subprocess.py:85} INFO - Output:
[2022-09-05 10:08:18,223] {subprocess.py:92} INFO - bash: line 1: /var/lib/mysql-files/data/20181024_d1_0830_0900.csv: No such file or directory
[2022-09-05 10:08:18,224] {subprocess.py:96} INFO - Command exited with return code 127
[2022-09-05 10:08:18,254] {taskinstance.py:1909} ERROR - Task failed with exception
Traceback (most recent call last):
  File "/home/airflow/.local/lib/python3.7/site-packages/airflow/operators/bash.py", line 195, in execute
    f'Bash command failed. The command returned a non-zero exit code {result.exit_code}.'
airflow.exceptions.AirflowException: Bash command failed. The command returned a non-zero exit code 127.
[2022-09-05 10:08:18,263] {taskinstance.py:1420} INFO - Marking task as FAILED. dag_id=create_tables, task_id=check_file, execution_date=20220901T000000, start_date=20220905T100817, end_date=20220905T100818
[2022-09-05 10:08:18,306] {standard_task_runner.py:97} ERROR - Failed to execute job 84 for task check_file (Bash command failed. The command returned a non-zero exit code 127.; 739)
[2022-09-05 10:08:18,339] {local_task_job.py:156} INFO - Task exited with return code 1
[2022-09-05 10:08:18,528] {local_task_job.py:273} INFO - 0 downstream tasks scheduled from follow-on schedule check
