[2022-09-05 10:12:29,886] {taskinstance.py:1179} INFO - Dependencies all met for <TaskInstance: create_tables.check_file scheduled__2022-09-01T00:00:00+00:00 [queued]>
[2022-09-05 10:12:29,923] {taskinstance.py:1179} INFO - Dependencies all met for <TaskInstance: create_tables.check_file scheduled__2022-09-01T00:00:00+00:00 [queued]>
[2022-09-05 10:12:29,923] {taskinstance.py:1376} INFO - 
--------------------------------------------------------------------------------
[2022-09-05 10:12:29,924] {taskinstance.py:1377} INFO - Starting attempt 19 of 21
[2022-09-05 10:12:29,925] {taskinstance.py:1378} INFO - 
--------------------------------------------------------------------------------
[2022-09-05 10:12:30,027] {taskinstance.py:1397} INFO - Executing <Task(BashOperator): check_file> on 2022-09-01 00:00:00+00:00
[2022-09-05 10:12:30,034] {standard_task_runner.py:52} INFO - Started process 941 to run task
[2022-09-05 10:12:30,039] {standard_task_runner.py:79} INFO - Running: ['***', 'tasks', 'run', 'create_tables', 'check_file', 'scheduled__2022-09-01T00:00:00+00:00', '--job-id', '106', '--raw', '--subdir', 'DAGS_FOLDER/create.py', '--cfg-path', '/tmp/tmpnx2163db', '--error-file', '/tmp/tmput9gbt5c']
[2022-09-05 10:12:30,040] {standard_task_runner.py:80} INFO - Job 106: Subtask check_file
[2022-09-05 10:12:30,227] {task_command.py:371} INFO - Running <TaskInstance: create_tables.check_file scheduled__2022-09-01T00:00:00+00:00 [running]> on host 613319c2eb0f
[2022-09-05 10:12:30,716] {taskinstance.py:1591} INFO - Exporting the following env vars:
AIRFLOW_CTX_DAG_OWNER=***
AIRFLOW_CTX_DAG_ID=create_tables
AIRFLOW_CTX_TASK_ID=check_file
AIRFLOW_CTX_EXECUTION_DATE=2022-09-01T00:00:00+00:00
AIRFLOW_CTX_TRY_NUMBER=19
AIRFLOW_CTX_DAG_RUN_ID=scheduled__2022-09-01T00:00:00+00:00
[2022-09-05 10:12:30,719] {subprocess.py:62} INFO - Tmp dir root location: 
 /tmp
[2022-09-05 10:12:30,720] {subprocess.py:74} INFO - Running command: ['bash', '-c', 'shasum ~ /data/20181024_d1_0830_0900.csv']
[2022-09-05 10:12:30,758] {subprocess.py:85} INFO - Output:
[2022-09-05 10:12:30,820] {subprocess.py:92} INFO - shasum: /home/***: Is a directory
[2022-09-05 10:12:30,821] {subprocess.py:92} INFO - shasum: /data/20181024_d1_0830_0900.csv: No such file or directory
[2022-09-05 10:12:30,822] {subprocess.py:96} INFO - Command exited with return code 1
[2022-09-05 10:12:30,856] {taskinstance.py:1909} ERROR - Task failed with exception
Traceback (most recent call last):
  File "/home/airflow/.local/lib/python3.7/site-packages/airflow/operators/bash.py", line 195, in execute
    f'Bash command failed. The command returned a non-zero exit code {result.exit_code}.'
airflow.exceptions.AirflowException: Bash command failed. The command returned a non-zero exit code 1.
[2022-09-05 10:12:30,870] {taskinstance.py:1420} INFO - Marking task as UP_FOR_RETRY. dag_id=create_tables, task_id=check_file, execution_date=20220901T000000, start_date=20220905T101229, end_date=20220905T101230
[2022-09-05 10:12:30,934] {standard_task_runner.py:97} ERROR - Failed to execute job 106 for task check_file (Bash command failed. The command returned a non-zero exit code 1.; 941)
[2022-09-05 10:12:30,958] {local_task_job.py:156} INFO - Task exited with return code 1
[2022-09-05 10:12:31,265] {local_task_job.py:273} INFO - 0 downstream tasks scheduled from follow-on schedule check
