[2022-09-05 10:10:36,579] {taskinstance.py:1179} INFO - Dependencies all met for <TaskInstance: create_tables.check_file scheduled__2022-09-01T00:00:00+00:00 [queued]>
[2022-09-05 10:10:36,604] {taskinstance.py:1179} INFO - Dependencies all met for <TaskInstance: create_tables.check_file scheduled__2022-09-01T00:00:00+00:00 [queued]>
[2022-09-05 10:10:36,605] {taskinstance.py:1376} INFO - 
--------------------------------------------------------------------------------
[2022-09-05 10:10:36,605] {taskinstance.py:1377} INFO - Starting attempt 16 of 18
[2022-09-05 10:10:36,606] {taskinstance.py:1378} INFO - 
--------------------------------------------------------------------------------
[2022-09-05 10:10:36,671] {taskinstance.py:1397} INFO - Executing <Task(BashOperator): check_file> on 2022-09-01 00:00:00+00:00
[2022-09-05 10:10:36,685] {standard_task_runner.py:52} INFO - Started process 844 to run task
[2022-09-05 10:10:36,690] {standard_task_runner.py:79} INFO - Running: ['***', 'tasks', 'run', 'create_tables', 'check_file', 'scheduled__2022-09-01T00:00:00+00:00', '--job-id', '94', '--raw', '--subdir', 'DAGS_FOLDER/create.py', '--cfg-path', '/tmp/tmpntnbpcq5', '--error-file', '/tmp/tmpnadijzwt']
[2022-09-05 10:10:36,691] {standard_task_runner.py:80} INFO - Job 94: Subtask check_file
[2022-09-05 10:10:36,980] {task_command.py:371} INFO - Running <TaskInstance: create_tables.check_file scheduled__2022-09-01T00:00:00+00:00 [running]> on host 613319c2eb0f
[2022-09-05 10:10:37,325] {taskinstance.py:1591} INFO - Exporting the following env vars:
AIRFLOW_CTX_DAG_OWNER=***
AIRFLOW_CTX_DAG_ID=create_tables
AIRFLOW_CTX_TASK_ID=check_file
AIRFLOW_CTX_EXECUTION_DATE=2022-09-01T00:00:00+00:00
AIRFLOW_CTX_TRY_NUMBER=16
AIRFLOW_CTX_DAG_RUN_ID=scheduled__2022-09-01T00:00:00+00:00
[2022-09-05 10:10:37,328] {subprocess.py:62} INFO - Tmp dir root location: 
 /tmp
[2022-09-05 10:10:37,335] {subprocess.py:74} INFO - Running command: ['bash', '-c', ' ~ /data/20181024_d1_0830_0900.csv']
[2022-09-05 10:10:37,357] {subprocess.py:85} INFO - Output:
[2022-09-05 10:10:37,366] {subprocess.py:92} INFO - bash: line 1: /home/***: Is a directory
[2022-09-05 10:10:37,368] {subprocess.py:96} INFO - Command exited with return code 126
[2022-09-05 10:10:37,436] {taskinstance.py:1909} ERROR - Task failed with exception
Traceback (most recent call last):
  File "/home/airflow/.local/lib/python3.7/site-packages/airflow/operators/bash.py", line 195, in execute
    f'Bash command failed. The command returned a non-zero exit code {result.exit_code}.'
airflow.exceptions.AirflowException: Bash command failed. The command returned a non-zero exit code 126.
[2022-09-05 10:10:37,483] {taskinstance.py:1420} INFO - Marking task as UP_FOR_RETRY. dag_id=create_tables, task_id=check_file, execution_date=20220901T000000, start_date=20220905T101036, end_date=20220905T101037
[2022-09-05 10:10:37,629] {standard_task_runner.py:97} ERROR - Failed to execute job 94 for task check_file (Bash command failed. The command returned a non-zero exit code 126.; 844)
[2022-09-05 10:10:37,667] {local_task_job.py:156} INFO - Task exited with return code 1
[2022-09-05 10:10:37,867] {local_task_job.py:273} INFO - 0 downstream tasks scheduled from follow-on schedule check
