[2022-09-05 10:12:48,176] {taskinstance.py:1179} INFO - Dependencies all met for <TaskInstance: create_tables.check_file scheduled__2022-09-01T00:00:00+00:00 [queued]>
[2022-09-05 10:12:48,206] {taskinstance.py:1179} INFO - Dependencies all met for <TaskInstance: create_tables.check_file scheduled__2022-09-01T00:00:00+00:00 [queued]>
[2022-09-05 10:12:48,206] {taskinstance.py:1376} INFO - 
--------------------------------------------------------------------------------
[2022-09-05 10:12:48,207] {taskinstance.py:1377} INFO - Starting attempt 20 of 21
[2022-09-05 10:12:48,208] {taskinstance.py:1378} INFO - 
--------------------------------------------------------------------------------
[2022-09-05 10:12:48,283] {taskinstance.py:1397} INFO - Executing <Task(BashOperator): check_file> on 2022-09-01 00:00:00+00:00
[2022-09-05 10:12:48,290] {standard_task_runner.py:52} INFO - Started process 961 to run task
[2022-09-05 10:12:48,300] {standard_task_runner.py:79} INFO - Running: ['***', 'tasks', 'run', 'create_tables', 'check_file', 'scheduled__2022-09-01T00:00:00+00:00', '--job-id', '109', '--raw', '--subdir', 'DAGS_FOLDER/create.py', '--cfg-path', '/tmp/tmpc5kj_ayf', '--error-file', '/tmp/tmphf_u4a0a']
[2022-09-05 10:12:48,301] {standard_task_runner.py:80} INFO - Job 109: Subtask check_file
[2022-09-05 10:12:48,534] {task_command.py:371} INFO - Running <TaskInstance: create_tables.check_file scheduled__2022-09-01T00:00:00+00:00 [running]> on host 613319c2eb0f
[2022-09-05 10:12:48,840] {taskinstance.py:1591} INFO - Exporting the following env vars:
AIRFLOW_CTX_DAG_OWNER=***
AIRFLOW_CTX_DAG_ID=create_tables
AIRFLOW_CTX_TASK_ID=check_file
AIRFLOW_CTX_EXECUTION_DATE=2022-09-01T00:00:00+00:00
AIRFLOW_CTX_TRY_NUMBER=20
AIRFLOW_CTX_DAG_RUN_ID=scheduled__2022-09-01T00:00:00+00:00
[2022-09-05 10:12:48,842] {subprocess.py:62} INFO - Tmp dir root location: 
 /tmp
[2022-09-05 10:12:48,882] {subprocess.py:74} INFO - Running command: ['bash', '-c', 'shasum ~ /data/20181024_d1_0830_0900.csv']
[2022-09-05 10:12:48,899] {subprocess.py:85} INFO - Output:
[2022-09-05 10:12:48,959] {subprocess.py:92} INFO - shasum: /home/***: Is a directory
[2022-09-05 10:12:48,960] {subprocess.py:92} INFO - shasum: /data/20181024_d1_0830_0900.csv: No such file or directory
[2022-09-05 10:12:48,963] {subprocess.py:96} INFO - Command exited with return code 1
[2022-09-05 10:12:49,005] {taskinstance.py:1909} ERROR - Task failed with exception
Traceback (most recent call last):
  File "/home/airflow/.local/lib/python3.7/site-packages/airflow/operators/bash.py", line 195, in execute
    f'Bash command failed. The command returned a non-zero exit code {result.exit_code}.'
airflow.exceptions.AirflowException: Bash command failed. The command returned a non-zero exit code 1.
[2022-09-05 10:12:49,023] {taskinstance.py:1420} INFO - Marking task as UP_FOR_RETRY. dag_id=create_tables, task_id=check_file, execution_date=20220901T000000, start_date=20220905T101248, end_date=20220905T101249
[2022-09-05 10:12:49,208] {standard_task_runner.py:97} ERROR - Failed to execute job 109 for task check_file (Bash command failed. The command returned a non-zero exit code 1.; 961)
[2022-09-05 10:12:49,276] {local_task_job.py:156} INFO - Task exited with return code 1
[2022-09-05 10:12:49,461] {local_task_job.py:273} INFO - 0 downstream tasks scheduled from follow-on schedule check
