[2022-09-05 14:35:24,437] {taskinstance.py:1179} INFO - Dependencies all met for <TaskInstance: create_tables.check_file scheduled__2022-09-02T00:00:00+00:00 [queued]>
[2022-09-05 14:35:24,479] {taskinstance.py:1179} INFO - Dependencies all met for <TaskInstance: create_tables.check_file scheduled__2022-09-02T00:00:00+00:00 [queued]>
[2022-09-05 14:35:24,480] {taskinstance.py:1376} INFO - 
--------------------------------------------------------------------------------
[2022-09-05 14:35:24,480] {taskinstance.py:1377} INFO - Starting attempt 26 of 27
[2022-09-05 14:35:24,652] {taskinstance.py:1378} INFO - 
--------------------------------------------------------------------------------
[2022-09-05 14:35:24,875] {taskinstance.py:1397} INFO - Executing <Task(BashOperator): check_file> on 2022-09-02 00:00:00+00:00
[2022-09-05 14:35:24,954] {standard_task_runner.py:52} INFO - Started process 1270 to run task
[2022-09-05 14:35:24,992] {standard_task_runner.py:79} INFO - Running: ['***', 'tasks', 'run', 'create_tables', 'check_file', 'scheduled__2022-09-02T00:00:00+00:00', '--job-id', '143', '--raw', '--subdir', 'DAGS_FOLDER/create.py', '--cfg-path', '/tmp/tmpz6oyzeoj', '--error-file', '/tmp/tmpkrdceoin']
[2022-09-05 14:35:24,993] {standard_task_runner.py:80} INFO - Job 143: Subtask check_file
[2022-09-05 14:35:26,071] {task_command.py:371} INFO - Running <TaskInstance: create_tables.check_file scheduled__2022-09-02T00:00:00+00:00 [running]> on host cdeef4137858
[2022-09-05 14:35:27,238] {taskinstance.py:1591} INFO - Exporting the following env vars:
AIRFLOW_CTX_DAG_OWNER=***
AIRFLOW_CTX_DAG_ID=create_tables
AIRFLOW_CTX_TASK_ID=check_file
AIRFLOW_CTX_EXECUTION_DATE=2022-09-02T00:00:00+00:00
AIRFLOW_CTX_TRY_NUMBER=26
AIRFLOW_CTX_DAG_RUN_ID=scheduled__2022-09-02T00:00:00+00:00
[2022-09-05 14:35:27,241] {subprocess.py:62} INFO - Tmp dir root location: 
 /tmp
[2022-09-05 14:35:27,243] {subprocess.py:74} INFO - Running command: ['bash', '-c', '/var/lib/mysql-files/data/20181024_d1_0830_0900.csv']
[2022-09-05 14:35:27,277] {subprocess.py:85} INFO - Output:
[2022-09-05 14:35:27,286] {subprocess.py:92} INFO - bash: line 1: /var/lib/mysql-files/data/20181024_d1_0830_0900.csv: No such file or directory
[2022-09-05 14:35:27,287] {subprocess.py:96} INFO - Command exited with return code 127
[2022-09-05 14:35:27,357] {taskinstance.py:1909} ERROR - Task failed with exception
Traceback (most recent call last):
  File "/home/airflow/.local/lib/python3.7/site-packages/airflow/operators/bash.py", line 195, in execute
    f'Bash command failed. The command returned a non-zero exit code {result.exit_code}.'
airflow.exceptions.AirflowException: Bash command failed. The command returned a non-zero exit code 127.
[2022-09-05 14:35:27,370] {taskinstance.py:1420} INFO - Marking task as UP_FOR_RETRY. dag_id=create_tables, task_id=check_file, execution_date=20220902T000000, start_date=20220905T143524, end_date=20220905T143527
[2022-09-05 14:35:28,174] {standard_task_runner.py:97} ERROR - Failed to execute job 143 for task check_file (Bash command failed. The command returned a non-zero exit code 127.; 1270)
[2022-09-05 14:35:28,226] {local_task_job.py:156} INFO - Task exited with return code 1
[2022-09-05 14:35:29,276] {local_task_job.py:273} INFO - 0 downstream tasks scheduled from follow-on schedule check
