[2022-09-05 09:54:37,045] {taskinstance.py:1179} INFO - Dependencies all met for <TaskInstance: create_tables.check_file scheduled__2022-09-02T00:00:00+00:00 [queued]>
[2022-09-05 09:54:37,072] {taskinstance.py:1179} INFO - Dependencies all met for <TaskInstance: create_tables.check_file scheduled__2022-09-02T00:00:00+00:00 [queued]>
[2022-09-05 09:54:37,073] {taskinstance.py:1376} INFO - 
--------------------------------------------------------------------------------
[2022-09-05 09:54:37,073] {taskinstance.py:1377} INFO - Starting attempt 9 of 9
[2022-09-05 09:54:37,074] {taskinstance.py:1378} INFO - 
--------------------------------------------------------------------------------
[2022-09-05 09:54:37,181] {taskinstance.py:1397} INFO - Executing <Task(BashOperator): check_file> on 2022-09-02 00:00:00+00:00
[2022-09-05 09:54:37,191] {standard_task_runner.py:52} INFO - Started process 189 to run task
[2022-09-05 09:54:37,197] {standard_task_runner.py:79} INFO - Running: ['***', 'tasks', 'run', 'create_tables', 'check_file', 'scheduled__2022-09-02T00:00:00+00:00', '--job-id', '51', '--raw', '--subdir', 'DAGS_FOLDER/create.py', '--cfg-path', '/tmp/tmpag28td58', '--error-file', '/tmp/tmp0kibdh3j']
[2022-09-05 09:54:37,198] {standard_task_runner.py:80} INFO - Job 51: Subtask check_file
[2022-09-05 09:54:37,463] {task_command.py:371} INFO - Running <TaskInstance: create_tables.check_file scheduled__2022-09-02T00:00:00+00:00 [running]> on host 613319c2eb0f
[2022-09-05 09:54:37,805] {taskinstance.py:1591} INFO - Exporting the following env vars:
AIRFLOW_CTX_DAG_OWNER=***
AIRFLOW_CTX_DAG_ID=create_tables
AIRFLOW_CTX_TASK_ID=check_file
AIRFLOW_CTX_EXECUTION_DATE=2022-09-02T00:00:00+00:00
AIRFLOW_CTX_TRY_NUMBER=9
AIRFLOW_CTX_DAG_RUN_ID=scheduled__2022-09-02T00:00:00+00:00
[2022-09-05 09:54:37,832] {subprocess.py:62} INFO - Tmp dir root location: 
 /tmp
[2022-09-05 09:54:37,833] {subprocess.py:74} INFO - Running command: ['bash', '-c', 'shasum ~/data/20181024_d1_0830_0900.csv']
[2022-09-05 09:54:37,925] {subprocess.py:85} INFO - Output:
[2022-09-05 09:54:37,977] {subprocess.py:92} INFO - shasum: /home/***/data/20181024_d1_0830_0900.csv: No such file or directory
[2022-09-05 09:54:37,978] {subprocess.py:96} INFO - Command exited with return code 1
[2022-09-05 09:54:38,009] {taskinstance.py:1909} ERROR - Task failed with exception
Traceback (most recent call last):
  File "/home/airflow/.local/lib/python3.7/site-packages/airflow/operators/bash.py", line 195, in execute
    f'Bash command failed. The command returned a non-zero exit code {result.exit_code}.'
airflow.exceptions.AirflowException: Bash command failed. The command returned a non-zero exit code 1.
[2022-09-05 09:54:38,021] {taskinstance.py:1420} INFO - Marking task as FAILED. dag_id=create_tables, task_id=check_file, execution_date=20220902T000000, start_date=20220905T095437, end_date=20220905T095438
[2022-09-05 09:54:38,221] {standard_task_runner.py:97} ERROR - Failed to execute job 51 for task check_file (Bash command failed. The command returned a non-zero exit code 1.; 189)
[2022-09-05 09:54:38,241] {local_task_job.py:156} INFO - Task exited with return code 1
[2022-09-05 09:54:38,441] {local_task_job.py:273} INFO - 0 downstream tasks scheduled from follow-on schedule check
