[2022-09-05 10:10:30,864] {taskinstance.py:1179} INFO - Dependencies all met for <TaskInstance: create_tables.check_file scheduled__2022-09-02T00:00:00+00:00 [queued]>
[2022-09-05 10:10:30,928] {taskinstance.py:1179} INFO - Dependencies all met for <TaskInstance: create_tables.check_file scheduled__2022-09-02T00:00:00+00:00 [queued]>
[2022-09-05 10:10:30,931] {taskinstance.py:1376} INFO - 
--------------------------------------------------------------------------------
[2022-09-05 10:10:30,931] {taskinstance.py:1377} INFO - Starting attempt 16 of 18
[2022-09-05 10:10:30,960] {taskinstance.py:1378} INFO - 
--------------------------------------------------------------------------------
[2022-09-05 10:10:31,365] {taskinstance.py:1397} INFO - Executing <Task(BashOperator): check_file> on 2022-09-02 00:00:00+00:00
[2022-09-05 10:10:31,391] {standard_task_runner.py:52} INFO - Started process 838 to run task
[2022-09-05 10:10:31,402] {standard_task_runner.py:79} INFO - Running: ['***', 'tasks', 'run', 'create_tables', 'check_file', 'scheduled__2022-09-02T00:00:00+00:00', '--job-id', '90', '--raw', '--subdir', 'DAGS_FOLDER/create.py', '--cfg-path', '/tmp/tmpl2v14chp', '--error-file', '/tmp/tmpwmllx6ou']
[2022-09-05 10:10:31,406] {standard_task_runner.py:80} INFO - Job 90: Subtask check_file
[2022-09-05 10:10:31,939] {task_command.py:371} INFO - Running <TaskInstance: create_tables.check_file scheduled__2022-09-02T00:00:00+00:00 [running]> on host 613319c2eb0f
[2022-09-05 10:10:33,033] {taskinstance.py:1591} INFO - Exporting the following env vars:
AIRFLOW_CTX_DAG_OWNER=***
AIRFLOW_CTX_DAG_ID=create_tables
AIRFLOW_CTX_TASK_ID=check_file
AIRFLOW_CTX_EXECUTION_DATE=2022-09-02T00:00:00+00:00
AIRFLOW_CTX_TRY_NUMBER=16
AIRFLOW_CTX_DAG_RUN_ID=scheduled__2022-09-02T00:00:00+00:00
[2022-09-05 10:10:33,035] {subprocess.py:62} INFO - Tmp dir root location: 
 /tmp
[2022-09-05 10:10:33,037] {subprocess.py:74} INFO - Running command: ['bash', '-c', ' ~ /data/20181024_d1_0830_0900.csv']
[2022-09-05 10:10:33,068] {subprocess.py:85} INFO - Output:
[2022-09-05 10:10:33,077] {subprocess.py:92} INFO - bash: line 1: /home/***: Is a directory
[2022-09-05 10:10:33,077] {subprocess.py:96} INFO - Command exited with return code 126
[2022-09-05 10:10:33,142] {taskinstance.py:1909} ERROR - Task failed with exception
Traceback (most recent call last):
  File "/home/airflow/.local/lib/python3.7/site-packages/airflow/operators/bash.py", line 195, in execute
    f'Bash command failed. The command returned a non-zero exit code {result.exit_code}.'
airflow.exceptions.AirflowException: Bash command failed. The command returned a non-zero exit code 126.
[2022-09-05 10:10:33,157] {taskinstance.py:1420} INFO - Marking task as UP_FOR_RETRY. dag_id=create_tables, task_id=check_file, execution_date=20220902T000000, start_date=20220905T101030, end_date=20220905T101033
[2022-09-05 10:10:33,316] {standard_task_runner.py:97} ERROR - Failed to execute job 90 for task check_file (Bash command failed. The command returned a non-zero exit code 126.; 838)
[2022-09-05 10:10:33,538] {local_task_job.py:156} INFO - Task exited with return code 1
[2022-09-05 10:10:33,944] {local_task_job.py:273} INFO - 0 downstream tasks scheduled from follow-on schedule check
