[2022-09-05 10:04:39,884] {taskinstance.py:1179} INFO - Dependencies all met for <TaskInstance: create_tables.check_file scheduled__2022-09-02T00:00:00+00:00 [queued]>
[2022-09-05 10:04:39,914] {taskinstance.py:1179} INFO - Dependencies all met for <TaskInstance: create_tables.check_file scheduled__2022-09-02T00:00:00+00:00 [queued]>
[2022-09-05 10:04:39,919] {taskinstance.py:1376} INFO - 
--------------------------------------------------------------------------------
[2022-09-05 10:04:39,920] {taskinstance.py:1377} INFO - Starting attempt 11 of 12
[2022-09-05 10:04:39,966] {taskinstance.py:1378} INFO - 
--------------------------------------------------------------------------------
[2022-09-05 10:04:40,112] {taskinstance.py:1397} INFO - Executing <Task(BashOperator): check_file> on 2022-09-02 00:00:00+00:00
[2022-09-05 10:04:40,126] {standard_task_runner.py:52} INFO - Started process 554 to run task
[2022-09-05 10:04:40,132] {standard_task_runner.py:79} INFO - Running: ['***', 'tasks', 'run', 'create_tables', 'check_file', 'scheduled__2022-09-02T00:00:00+00:00', '--job-id', '64', '--raw', '--subdir', 'DAGS_FOLDER/create.py', '--cfg-path', '/tmp/tmp_x8orh4x', '--error-file', '/tmp/tmpxvu8rhh5']
[2022-09-05 10:04:40,146] {standard_task_runner.py:80} INFO - Job 64: Subtask check_file
[2022-09-05 10:04:40,561] {task_command.py:371} INFO - Running <TaskInstance: create_tables.check_file scheduled__2022-09-02T00:00:00+00:00 [running]> on host 613319c2eb0f
[2022-09-05 10:04:40,971] {taskinstance.py:1591} INFO - Exporting the following env vars:
AIRFLOW_CTX_DAG_OWNER=***
AIRFLOW_CTX_DAG_ID=create_tables
AIRFLOW_CTX_TASK_ID=check_file
AIRFLOW_CTX_EXECUTION_DATE=2022-09-02T00:00:00+00:00
AIRFLOW_CTX_TRY_NUMBER=11
AIRFLOW_CTX_DAG_RUN_ID=scheduled__2022-09-02T00:00:00+00:00
[2022-09-05 10:04:41,092] {subprocess.py:62} INFO - Tmp dir root location: 
 /tmp
[2022-09-05 10:04:41,206] {subprocess.py:74} INFO - Running command: ['bash', '-c', '/var/lib/mysql-files/data/20181024_d1_0830_0900.csv']
[2022-09-05 10:04:41,332] {subprocess.py:85} INFO - Output:
[2022-09-05 10:04:41,347] {subprocess.py:92} INFO - bash: line 1: /var/lib/mysql-files/data/20181024_d1_0830_0900.csv: No such file or directory
[2022-09-05 10:04:41,356] {subprocess.py:96} INFO - Command exited with return code 127
[2022-09-05 10:04:41,650] {taskinstance.py:1909} ERROR - Task failed with exception
Traceback (most recent call last):
  File "/home/airflow/.local/lib/python3.7/site-packages/airflow/operators/bash.py", line 195, in execute
    f'Bash command failed. The command returned a non-zero exit code {result.exit_code}.'
airflow.exceptions.AirflowException: Bash command failed. The command returned a non-zero exit code 127.
[2022-09-05 10:04:41,688] {taskinstance.py:1420} INFO - Marking task as UP_FOR_RETRY. dag_id=create_tables, task_id=check_file, execution_date=20220902T000000, start_date=20220905T100439, end_date=20220905T100441
[2022-09-05 10:04:41,785] {standard_task_runner.py:97} ERROR - Failed to execute job 64 for task check_file (Bash command failed. The command returned a non-zero exit code 127.; 554)
[2022-09-05 10:04:41,827] {local_task_job.py:156} INFO - Task exited with return code 1
[2022-09-05 10:04:42,366] {local_task_job.py:273} INFO - 0 downstream tasks scheduled from follow-on schedule check
