[2022-09-05 09:29:01,689] {taskinstance.py:1179} INFO - Dependencies all met for <TaskInstance: create_tables.test scheduled__2022-09-02T00:00:00+00:00 [queued]>
[2022-09-05 09:29:01,845] {taskinstance.py:1179} INFO - Dependencies all met for <TaskInstance: create_tables.test scheduled__2022-09-02T00:00:00+00:00 [queued]>
[2022-09-05 09:29:01,855] {taskinstance.py:1376} INFO - 
--------------------------------------------------------------------------------
[2022-09-05 09:29:01,883] {taskinstance.py:1377} INFO - Starting attempt 2 of 2
[2022-09-05 09:29:01,884] {taskinstance.py:1378} INFO - 
--------------------------------------------------------------------------------
[2022-09-05 09:29:02,241] {taskinstance.py:1397} INFO - Executing <Task(MySqlOperator): test> on 2022-09-02 00:00:00+00:00
[2022-09-05 09:29:02,264] {standard_task_runner.py:52} INFO - Started process 837 to run task
[2022-09-05 09:29:02,287] {standard_task_runner.py:79} INFO - Running: ['***', 'tasks', 'run', 'create_tables', 'test', 'scheduled__2022-09-02T00:00:00+00:00', '--job-id', '22', '--raw', '--subdir', 'DAGS_FOLDER/create.py', '--cfg-path', '/tmp/tmprwusu803', '--error-file', '/tmp/tmp4cgoa15v']
[2022-09-05 09:29:02,327] {standard_task_runner.py:80} INFO - Job 22: Subtask test
[2022-09-05 09:29:02,939] {task_command.py:371} INFO - Running <TaskInstance: create_tables.test scheduled__2022-09-02T00:00:00+00:00 [running]> on host bcd27e6a9f6c
[2022-09-05 09:29:03,635] {taskinstance.py:1591} INFO - Exporting the following env vars:
AIRFLOW_CTX_DAG_OWNER=***
AIRFLOW_CTX_DAG_ID=create_tables
AIRFLOW_CTX_TASK_ID=test
AIRFLOW_CTX_EXECUTION_DATE=2022-09-02T00:00:00+00:00
AIRFLOW_CTX_TRY_NUMBER=2
AIRFLOW_CTX_DAG_RUN_ID=scheduled__2022-09-02T00:00:00+00:00
[2022-09-05 09:29:03,636] {mysql.py:82} INFO - Executing: SHOW VARIABLES LIKE "secure_file_priv";
[2022-09-05 09:29:03,749] {taskinstance.py:1909} ERROR - Task failed with exception
Traceback (most recent call last):
  File "/home/airflow/.local/lib/python3.7/site-packages/airflow/providers/mysql/operators/mysql.py", line 84, in execute
    hook.run(self.sql, autocommit=self.autocommit, parameters=self.parameters)
  File "/home/airflow/.local/lib/python3.7/site-packages/airflow/hooks/dbapi.py", line 204, in run
    with closing(self.get_conn()) as conn:
  File "/home/airflow/.local/lib/python3.7/site-packages/airflow/providers/mysql/hooks/mysql.py", line 158, in get_conn
    conn = self.connection or self.get_connection(getattr(self, self.conn_name_attr))
  File "/home/airflow/.local/lib/python3.7/site-packages/airflow/hooks/base.py", line 67, in get_connection
    conn = Connection.get_connection_from_secrets(conn_id)
  File "/home/airflow/.local/lib/python3.7/site-packages/airflow/models/connection.py", line 430, in get_connection_from_secrets
    raise AirflowNotFoundException(f"The conn_id `{conn_id}` isn't defined")
airflow.exceptions.AirflowNotFoundException: The conn_id `mysql_conn_id` isn't defined
[2022-09-05 09:29:03,785] {taskinstance.py:1420} INFO - Marking task as FAILED. dag_id=create_tables, task_id=test, execution_date=20220902T000000, start_date=20220905T092901, end_date=20220905T092903
[2022-09-05 09:29:03,878] {standard_task_runner.py:97} ERROR - Failed to execute job 22 for task test (The conn_id `mysql_conn_id` isn't defined; 837)
[2022-09-05 09:29:03,921] {local_task_job.py:156} INFO - Task exited with return code 1
[2022-09-05 09:29:04,207] {local_task_job.py:273} INFO - 0 downstream tasks scheduled from follow-on schedule check
