[2022-09-05 09:54:31,070] {taskinstance.py:1179} INFO - Dependencies all met for <TaskInstance: create_tables.test scheduled__2022-09-02T00:00:00+00:00 [queued]>
[2022-09-05 09:54:31,201] {taskinstance.py:1179} INFO - Dependencies all met for <TaskInstance: create_tables.test scheduled__2022-09-02T00:00:00+00:00 [queued]>
[2022-09-05 09:54:31,202] {taskinstance.py:1376} INFO - 
--------------------------------------------------------------------------------
[2022-09-05 09:54:31,202] {taskinstance.py:1377} INFO - Starting attempt 4 of 4
[2022-09-05 09:54:31,203] {taskinstance.py:1378} INFO - 
--------------------------------------------------------------------------------
[2022-09-05 09:54:31,419] {taskinstance.py:1397} INFO - Executing <Task(MySqlOperator): test> on 2022-09-02 00:00:00+00:00
[2022-09-05 09:54:31,503] {standard_task_runner.py:52} INFO - Started process 183 to run task
[2022-09-05 09:54:31,520] {standard_task_runner.py:79} INFO - Running: ['***', 'tasks', 'run', 'create_tables', 'test', 'scheduled__2022-09-02T00:00:00+00:00', '--job-id', '49', '--raw', '--subdir', 'DAGS_FOLDER/create.py', '--cfg-path', '/tmp/tmpuwliqm8x', '--error-file', '/tmp/tmpkg8tgk6w']
[2022-09-05 09:54:31,521] {standard_task_runner.py:80} INFO - Job 49: Subtask test
[2022-09-05 09:54:32,461] {task_command.py:371} INFO - Running <TaskInstance: create_tables.test scheduled__2022-09-02T00:00:00+00:00 [running]> on host 613319c2eb0f
[2022-09-05 09:54:33,205] {taskinstance.py:1591} INFO - Exporting the following env vars:
AIRFLOW_CTX_DAG_OWNER=***
AIRFLOW_CTX_DAG_ID=create_tables
AIRFLOW_CTX_TASK_ID=test
AIRFLOW_CTX_EXECUTION_DATE=2022-09-02T00:00:00+00:00
AIRFLOW_CTX_TRY_NUMBER=4
AIRFLOW_CTX_DAG_RUN_ID=scheduled__2022-09-02T00:00:00+00:00
[2022-09-05 09:54:33,206] {mysql.py:82} INFO - Executing: SHOW VARIABLES LIKE "secure_file_priv";
[2022-09-05 09:54:33,276] {taskinstance.py:1909} ERROR - Task failed with exception
Traceback (most recent call last):
  File "/home/airflow/.local/lib/python3.7/site-packages/airflow/providers/mysql/operators/mysql.py", line 84, in execute
    hook.run(self.sql, autocommit=self.autocommit, parameters=self.parameters)
  File "/home/airflow/.local/lib/python3.7/site-packages/airflow/hooks/dbapi.py", line 204, in run
    with closing(self.get_conn()) as conn:
  File "/home/airflow/.local/lib/python3.7/site-packages/airflow/providers/mysql/hooks/mysql.py", line 158, in get_conn
    conn = self.connection or self.get_connection(getattr(self, self.conn_name_attr))
  File "/home/airflow/.local/lib/python3.7/site-packages/airflow/hooks/base.py", line 67, in get_connection
    conn = Connection.get_connection_from_secrets(conn_id)
  File "/home/airflow/.local/lib/python3.7/site-packages/airflow/models/connection.py", line 430, in get_connection_from_secrets
    raise AirflowNotFoundException(f"The conn_id `{conn_id}` isn't defined")
airflow.exceptions.AirflowNotFoundException: The conn_id `mysql_conn_id` isn't defined
[2022-09-05 09:54:33,326] {taskinstance.py:1420} INFO - Marking task as FAILED. dag_id=create_tables, task_id=test, execution_date=20220902T000000, start_date=20220905T095431, end_date=20220905T095433
[2022-09-05 09:54:33,464] {standard_task_runner.py:97} ERROR - Failed to execute job 49 for task test (The conn_id `mysql_conn_id` isn't defined; 183)
[2022-09-05 09:54:33,508] {local_task_job.py:156} INFO - Task exited with return code 1
[2022-09-05 09:54:33,714] {local_task_job.py:273} INFO - 0 downstream tasks scheduled from follow-on schedule check
