[2022-09-05 10:07:25,857] {taskinstance.py:1179} INFO - Dependencies all met for <TaskInstance: create_tables.check_file scheduled__2022-09-04T00:00:00+00:00 [queued]>
[2022-09-05 10:07:25,879] {taskinstance.py:1179} INFO - Dependencies all met for <TaskInstance: create_tables.check_file scheduled__2022-09-04T00:00:00+00:00 [queued]>
[2022-09-05 10:07:25,880] {taskinstance.py:1376} INFO - 
--------------------------------------------------------------------------------
[2022-09-05 10:07:25,881] {taskinstance.py:1377} INFO - Starting attempt 13 of 15
[2022-09-05 10:07:25,881] {taskinstance.py:1378} INFO - 
--------------------------------------------------------------------------------
[2022-09-05 10:07:25,947] {taskinstance.py:1397} INFO - Executing <Task(BashOperator): check_file> on 2022-09-04 00:00:00+00:00
[2022-09-05 10:07:25,953] {standard_task_runner.py:52} INFO - Started process 675 to run task
[2022-09-05 10:07:25,959] {standard_task_runner.py:79} INFO - Running: ['***', 'tasks', 'run', 'create_tables', 'check_file', 'scheduled__2022-09-04T00:00:00+00:00', '--job-id', '70', '--raw', '--subdir', 'DAGS_FOLDER/create.py', '--cfg-path', '/tmp/tmpopg2czm0', '--error-file', '/tmp/tmptjd585ga']
[2022-09-05 10:07:25,960] {standard_task_runner.py:80} INFO - Job 70: Subtask check_file
[2022-09-05 10:07:26,138] {task_command.py:371} INFO - Running <TaskInstance: create_tables.check_file scheduled__2022-09-04T00:00:00+00:00 [running]> on host 613319c2eb0f
[2022-09-05 10:07:26,323] {taskinstance.py:1591} INFO - Exporting the following env vars:
AIRFLOW_CTX_DAG_OWNER=***
AIRFLOW_CTX_DAG_ID=create_tables
AIRFLOW_CTX_TASK_ID=check_file
AIRFLOW_CTX_EXECUTION_DATE=2022-09-04T00:00:00+00:00
AIRFLOW_CTX_TRY_NUMBER=13
AIRFLOW_CTX_DAG_RUN_ID=scheduled__2022-09-04T00:00:00+00:00
[2022-09-05 10:07:26,325] {subprocess.py:62} INFO - Tmp dir root location: 
 /tmp
[2022-09-05 10:07:26,326] {subprocess.py:74} INFO - Running command: ['bash', '-c', '/var/lib/mysql-files/data/20181024_d1_0830_0900.csv']
[2022-09-05 10:07:26,342] {subprocess.py:85} INFO - Output:
[2022-09-05 10:07:26,353] {subprocess.py:92} INFO - bash: line 1: /var/lib/mysql-files/data/20181024_d1_0830_0900.csv: No such file or directory
[2022-09-05 10:07:26,354] {subprocess.py:96} INFO - Command exited with return code 127
[2022-09-05 10:07:26,386] {taskinstance.py:1909} ERROR - Task failed with exception
Traceback (most recent call last):
  File "/home/airflow/.local/lib/python3.7/site-packages/airflow/operators/bash.py", line 195, in execute
    f'Bash command failed. The command returned a non-zero exit code {result.exit_code}.'
airflow.exceptions.AirflowException: Bash command failed. The command returned a non-zero exit code 127.
[2022-09-05 10:07:26,399] {taskinstance.py:1420} INFO - Marking task as UP_FOR_RETRY. dag_id=create_tables, task_id=check_file, execution_date=20220904T000000, start_date=20220905T100725, end_date=20220905T100726
[2022-09-05 10:07:26,471] {standard_task_runner.py:97} ERROR - Failed to execute job 70 for task check_file (Bash command failed. The command returned a non-zero exit code 127.; 675)
[2022-09-05 10:07:26,497] {local_task_job.py:156} INFO - Task exited with return code 1
[2022-09-05 10:07:26,646] {local_task_job.py:273} INFO - 0 downstream tasks scheduled from follow-on schedule check
