[2022-09-05 14:26:55,554] {taskinstance.py:1179} INFO - Dependencies all met for <TaskInstance: create_tables.check_file scheduled__2022-09-04T00:00:00+00:00 [queued]>
[2022-09-05 14:26:55,594] {taskinstance.py:1179} INFO - Dependencies all met for <TaskInstance: create_tables.check_file scheduled__2022-09-04T00:00:00+00:00 [queued]>
[2022-09-05 14:26:55,595] {taskinstance.py:1376} INFO - 
--------------------------------------------------------------------------------
[2022-09-05 14:26:55,596] {taskinstance.py:1377} INFO - Starting attempt 23 of 24
[2022-09-05 14:26:55,597] {taskinstance.py:1378} INFO - 
--------------------------------------------------------------------------------
[2022-09-05 14:26:55,751] {taskinstance.py:1397} INFO - Executing <Task(BashOperator): check_file> on 2022-09-04 00:00:00+00:00
[2022-09-05 14:26:55,765] {standard_task_runner.py:52} INFO - Started process 946 to run task
[2022-09-05 14:26:55,774] {standard_task_runner.py:79} INFO - Running: ['***', 'tasks', 'run', 'create_tables', 'check_file', 'scheduled__2022-09-04T00:00:00+00:00', '--job-id', '127', '--raw', '--subdir', 'DAGS_FOLDER/create.py', '--cfg-path', '/tmp/tmpbsbl2m_l', '--error-file', '/tmp/tmpx8hov_sz']
[2022-09-05 14:26:55,775] {standard_task_runner.py:80} INFO - Job 127: Subtask check_file
[2022-09-05 14:26:55,998] {task_command.py:371} INFO - Running <TaskInstance: create_tables.check_file scheduled__2022-09-04T00:00:00+00:00 [running]> on host cdeef4137858
[2022-09-05 14:26:56,190] {taskinstance.py:1591} INFO - Exporting the following env vars:
AIRFLOW_CTX_DAG_OWNER=***
AIRFLOW_CTX_DAG_ID=create_tables
AIRFLOW_CTX_TASK_ID=check_file
AIRFLOW_CTX_EXECUTION_DATE=2022-09-04T00:00:00+00:00
AIRFLOW_CTX_TRY_NUMBER=23
AIRFLOW_CTX_DAG_RUN_ID=scheduled__2022-09-04T00:00:00+00:00
[2022-09-05 14:26:56,192] {subprocess.py:62} INFO - Tmp dir root location: 
 /tmp
[2022-09-05 14:26:56,194] {subprocess.py:74} INFO - Running command: ['bash', '-c', 'shasum ~ /data/20181024_d1_0830_0900.csv']
[2022-09-05 14:26:56,210] {subprocess.py:85} INFO - Output:
[2022-09-05 14:26:56,256] {subprocess.py:92} INFO - shasum: /home/***: Is a directory
[2022-09-05 14:26:56,256] {subprocess.py:92} INFO - shasum: /data/20181024_d1_0830_0900.csv: No such file or directory
[2022-09-05 14:26:56,257] {subprocess.py:96} INFO - Command exited with return code 1
[2022-09-05 14:26:56,292] {taskinstance.py:1909} ERROR - Task failed with exception
Traceback (most recent call last):
  File "/home/airflow/.local/lib/python3.7/site-packages/airflow/operators/bash.py", line 195, in execute
    f'Bash command failed. The command returned a non-zero exit code {result.exit_code}.'
airflow.exceptions.AirflowException: Bash command failed. The command returned a non-zero exit code 1.
[2022-09-05 14:26:56,303] {taskinstance.py:1420} INFO - Marking task as UP_FOR_RETRY. dag_id=create_tables, task_id=check_file, execution_date=20220904T000000, start_date=20220905T142655, end_date=20220905T142656
[2022-09-05 14:26:56,365] {standard_task_runner.py:97} ERROR - Failed to execute job 127 for task check_file (Bash command failed. The command returned a non-zero exit code 1.; 946)
[2022-09-05 14:26:56,426] {local_task_job.py:156} INFO - Task exited with return code 1
[2022-09-05 14:26:56,669] {local_task_job.py:273} INFO - 0 downstream tasks scheduled from follow-on schedule check
