[2022-09-05 09:54:07,415] {taskinstance.py:1179} INFO - Dependencies all met for <TaskInstance: create_tables.check_file scheduled__2022-09-04T00:00:00+00:00 [queued]>
[2022-09-05 09:54:07,458] {taskinstance.py:1179} INFO - Dependencies all met for <TaskInstance: create_tables.check_file scheduled__2022-09-04T00:00:00+00:00 [queued]>
[2022-09-05 09:54:07,487] {taskinstance.py:1376} INFO - 
--------------------------------------------------------------------------------
[2022-09-05 09:54:07,496] {taskinstance.py:1377} INFO - Starting attempt 8 of 9
[2022-09-05 09:54:07,537] {taskinstance.py:1378} INFO - 
--------------------------------------------------------------------------------
[2022-09-05 09:54:07,736] {taskinstance.py:1397} INFO - Executing <Task(BashOperator): check_file> on 2022-09-04 00:00:00+00:00
[2022-09-05 09:54:07,760] {standard_task_runner.py:52} INFO - Started process 146 to run task
[2022-09-05 09:54:07,762] {standard_task_runner.py:79} INFO - Running: ['***', 'tasks', 'run', 'create_tables', 'check_file', 'scheduled__2022-09-04T00:00:00+00:00', '--job-id', '42', '--raw', '--subdir', 'DAGS_FOLDER/create.py', '--cfg-path', '/tmp/tmpil97j1mb', '--error-file', '/tmp/tmptgh7n2bi']
[2022-09-05 09:54:07,769] {standard_task_runner.py:80} INFO - Job 42: Subtask check_file
[2022-09-05 09:54:08,161] {task_command.py:371} INFO - Running <TaskInstance: create_tables.check_file scheduled__2022-09-04T00:00:00+00:00 [running]> on host 613319c2eb0f
[2022-09-05 09:54:08,681] {taskinstance.py:1591} INFO - Exporting the following env vars:
AIRFLOW_CTX_DAG_OWNER=***
AIRFLOW_CTX_DAG_ID=create_tables
AIRFLOW_CTX_TASK_ID=check_file
AIRFLOW_CTX_EXECUTION_DATE=2022-09-04T00:00:00+00:00
AIRFLOW_CTX_TRY_NUMBER=8
AIRFLOW_CTX_DAG_RUN_ID=scheduled__2022-09-04T00:00:00+00:00
[2022-09-05 09:54:08,700] {subprocess.py:62} INFO - Tmp dir root location: 
 /tmp
[2022-09-05 09:54:08,705] {subprocess.py:74} INFO - Running command: ['bash', '-c', 'shasum ~/data/20181024_d1_0830_0900.csv']
[2022-09-05 09:54:08,893] {subprocess.py:85} INFO - Output:
[2022-09-05 09:54:08,970] {subprocess.py:92} INFO - shasum: /home/***/data/20181024_d1_0830_0900.csv: No such file or directory
[2022-09-05 09:54:08,971] {subprocess.py:96} INFO - Command exited with return code 1
[2022-09-05 09:54:09,134] {taskinstance.py:1909} ERROR - Task failed with exception
Traceback (most recent call last):
  File "/home/airflow/.local/lib/python3.7/site-packages/airflow/operators/bash.py", line 195, in execute
    f'Bash command failed. The command returned a non-zero exit code {result.exit_code}.'
airflow.exceptions.AirflowException: Bash command failed. The command returned a non-zero exit code 1.
[2022-09-05 09:54:09,263] {taskinstance.py:1420} INFO - Marking task as UP_FOR_RETRY. dag_id=create_tables, task_id=check_file, execution_date=20220904T000000, start_date=20220905T095407, end_date=20220905T095409
[2022-09-05 09:54:09,482] {standard_task_runner.py:97} ERROR - Failed to execute job 42 for task check_file (Bash command failed. The command returned a non-zero exit code 1.; 146)
[2022-09-05 09:54:09,555] {local_task_job.py:156} INFO - Task exited with return code 1
[2022-09-05 09:54:10,177] {local_task_job.py:273} INFO - 0 downstream tasks scheduled from follow-on schedule check
