[2022-09-05 14:26:37,483] {taskinstance.py:1179} INFO - Dependencies all met for <TaskInstance: create_tables.check_file scheduled__2022-09-04T00:00:00+00:00 [queued]>
[2022-09-05 14:26:37,515] {taskinstance.py:1179} INFO - Dependencies all met for <TaskInstance: create_tables.check_file scheduled__2022-09-04T00:00:00+00:00 [queued]>
[2022-09-05 14:26:37,515] {taskinstance.py:1376} INFO - 
--------------------------------------------------------------------------------
[2022-09-05 14:26:37,516] {taskinstance.py:1377} INFO - Starting attempt 22 of 24
[2022-09-05 14:26:37,524] {taskinstance.py:1378} INFO - 
--------------------------------------------------------------------------------
[2022-09-05 14:26:37,653] {taskinstance.py:1397} INFO - Executing <Task(BashOperator): check_file> on 2022-09-04 00:00:00+00:00
[2022-09-05 14:26:37,663] {standard_task_runner.py:52} INFO - Started process 924 to run task
[2022-09-05 14:26:37,674] {standard_task_runner.py:79} INFO - Running: ['***', 'tasks', 'run', 'create_tables', 'check_file', 'scheduled__2022-09-04T00:00:00+00:00', '--job-id', '122', '--raw', '--subdir', 'DAGS_FOLDER/create.py', '--cfg-path', '/tmp/tmpb154o40e', '--error-file', '/tmp/tmpau0b7wsr']
[2022-09-05 14:26:37,679] {standard_task_runner.py:80} INFO - Job 122: Subtask check_file
[2022-09-05 14:26:37,976] {task_command.py:371} INFO - Running <TaskInstance: create_tables.check_file scheduled__2022-09-04T00:00:00+00:00 [running]> on host cdeef4137858
[2022-09-05 14:26:38,480] {taskinstance.py:1591} INFO - Exporting the following env vars:
AIRFLOW_CTX_DAG_OWNER=***
AIRFLOW_CTX_DAG_ID=create_tables
AIRFLOW_CTX_TASK_ID=check_file
AIRFLOW_CTX_EXECUTION_DATE=2022-09-04T00:00:00+00:00
AIRFLOW_CTX_TRY_NUMBER=22
AIRFLOW_CTX_DAG_RUN_ID=scheduled__2022-09-04T00:00:00+00:00
[2022-09-05 14:26:38,496] {subprocess.py:62} INFO - Tmp dir root location: 
 /tmp
[2022-09-05 14:26:38,498] {subprocess.py:74} INFO - Running command: ['bash', '-c', 'shasum ~ /data/20181024_d1_0830_0900.csv']
[2022-09-05 14:26:38,546] {subprocess.py:85} INFO - Output:
[2022-09-05 14:26:38,660] {subprocess.py:92} INFO - shasum: /home/***: Is a directory
[2022-09-05 14:26:38,664] {subprocess.py:92} INFO - shasum: /data/20181024_d1_0830_0900.csv: No such file or directory
[2022-09-05 14:26:38,667] {subprocess.py:96} INFO - Command exited with return code 1
[2022-09-05 14:26:38,740] {taskinstance.py:1909} ERROR - Task failed with exception
Traceback (most recent call last):
  File "/home/airflow/.local/lib/python3.7/site-packages/airflow/operators/bash.py", line 195, in execute
    f'Bash command failed. The command returned a non-zero exit code {result.exit_code}.'
airflow.exceptions.AirflowException: Bash command failed. The command returned a non-zero exit code 1.
[2022-09-05 14:26:38,753] {taskinstance.py:1420} INFO - Marking task as UP_FOR_RETRY. dag_id=create_tables, task_id=check_file, execution_date=20220904T000000, start_date=20220905T142637, end_date=20220905T142638
[2022-09-05 14:26:38,929] {standard_task_runner.py:97} ERROR - Failed to execute job 122 for task check_file (Bash command failed. The command returned a non-zero exit code 1.; 924)
[2022-09-05 14:26:38,982] {local_task_job.py:156} INFO - Task exited with return code 1
[2022-09-05 14:26:39,292] {local_task_job.py:273} INFO - 0 downstream tasks scheduled from follow-on schedule check
