[2022-09-05 10:08:00,289] {taskinstance.py:1179} INFO - Dependencies all met for <TaskInstance: create_tables.check_file scheduled__2022-09-04T00:00:00+00:00 [queued]>
[2022-09-05 10:08:00,311] {taskinstance.py:1179} INFO - Dependencies all met for <TaskInstance: create_tables.check_file scheduled__2022-09-04T00:00:00+00:00 [queued]>
[2022-09-05 10:08:00,312] {taskinstance.py:1376} INFO - 
--------------------------------------------------------------------------------
[2022-09-05 10:08:00,314] {taskinstance.py:1377} INFO - Starting attempt 15 of 15
[2022-09-05 10:08:00,326] {taskinstance.py:1378} INFO - 
--------------------------------------------------------------------------------
[2022-09-05 10:08:00,427] {taskinstance.py:1397} INFO - Executing <Task(BashOperator): check_file> on 2022-09-04 00:00:00+00:00
[2022-09-05 10:08:00,437] {standard_task_runner.py:52} INFO - Started process 720 to run task
[2022-09-05 10:08:00,443] {standard_task_runner.py:79} INFO - Running: ['***', 'tasks', 'run', 'create_tables', 'check_file', 'scheduled__2022-09-04T00:00:00+00:00', '--job-id', '81', '--raw', '--subdir', 'DAGS_FOLDER/create.py', '--cfg-path', '/tmp/tmpybxs5xps', '--error-file', '/tmp/tmpx0yvcp1z']
[2022-09-05 10:08:00,444] {standard_task_runner.py:80} INFO - Job 81: Subtask check_file
[2022-09-05 10:08:00,735] {task_command.py:371} INFO - Running <TaskInstance: create_tables.check_file scheduled__2022-09-04T00:00:00+00:00 [running]> on host 613319c2eb0f
[2022-09-05 10:08:00,906] {taskinstance.py:1591} INFO - Exporting the following env vars:
AIRFLOW_CTX_DAG_OWNER=***
AIRFLOW_CTX_DAG_ID=create_tables
AIRFLOW_CTX_TASK_ID=check_file
AIRFLOW_CTX_EXECUTION_DATE=2022-09-04T00:00:00+00:00
AIRFLOW_CTX_TRY_NUMBER=15
AIRFLOW_CTX_DAG_RUN_ID=scheduled__2022-09-04T00:00:00+00:00
[2022-09-05 10:08:00,908] {subprocess.py:62} INFO - Tmp dir root location: 
 /tmp
[2022-09-05 10:08:00,910] {subprocess.py:74} INFO - Running command: ['bash', '-c', '/var/lib/mysql-files/data/20181024_d1_0830_0900.csv']
[2022-09-05 10:08:00,925] {subprocess.py:85} INFO - Output:
[2022-09-05 10:08:00,935] {subprocess.py:92} INFO - bash: line 1: /var/lib/mysql-files/data/20181024_d1_0830_0900.csv: No such file or directory
[2022-09-05 10:08:00,936] {subprocess.py:96} INFO - Command exited with return code 127
[2022-09-05 10:08:00,965] {taskinstance.py:1909} ERROR - Task failed with exception
Traceback (most recent call last):
  File "/home/airflow/.local/lib/python3.7/site-packages/airflow/operators/bash.py", line 195, in execute
    f'Bash command failed. The command returned a non-zero exit code {result.exit_code}.'
airflow.exceptions.AirflowException: Bash command failed. The command returned a non-zero exit code 127.
[2022-09-05 10:08:00,976] {taskinstance.py:1420} INFO - Marking task as FAILED. dag_id=create_tables, task_id=check_file, execution_date=20220904T000000, start_date=20220905T100800, end_date=20220905T100800
[2022-09-05 10:08:01,028] {standard_task_runner.py:97} ERROR - Failed to execute job 81 for task check_file (Bash command failed. The command returned a non-zero exit code 127.; 720)
[2022-09-05 10:08:01,066] {local_task_job.py:156} INFO - Task exited with return code 1
[2022-09-05 10:08:01,204] {local_task_job.py:273} INFO - 0 downstream tasks scheduled from follow-on schedule check
