[2022-09-05 09:54:11,228] {taskinstance.py:1179} INFO - Dependencies all met for <TaskInstance: create_tables.check_file scheduled__2022-09-03T00:00:00+00:00 [queued]>
[2022-09-05 09:54:11,285] {taskinstance.py:1179} INFO - Dependencies all met for <TaskInstance: create_tables.check_file scheduled__2022-09-03T00:00:00+00:00 [queued]>
[2022-09-05 09:54:11,286] {taskinstance.py:1376} INFO - 
--------------------------------------------------------------------------------
[2022-09-05 09:54:11,287] {taskinstance.py:1377} INFO - Starting attempt 8 of 9
[2022-09-05 09:54:11,315] {taskinstance.py:1378} INFO - 
--------------------------------------------------------------------------------
[2022-09-05 09:54:11,643] {taskinstance.py:1397} INFO - Executing <Task(BashOperator): check_file> on 2022-09-03 00:00:00+00:00
[2022-09-05 09:54:11,664] {standard_task_runner.py:52} INFO - Started process 156 to run task
[2022-09-05 09:54:11,671] {standard_task_runner.py:79} INFO - Running: ['***', 'tasks', 'run', 'create_tables', 'check_file', 'scheduled__2022-09-03T00:00:00+00:00', '--job-id', '43', '--raw', '--subdir', 'DAGS_FOLDER/create.py', '--cfg-path', '/tmp/tmpmq5o4ppd', '--error-file', '/tmp/tmplwlxbz1a']
[2022-09-05 09:54:11,708] {standard_task_runner.py:80} INFO - Job 43: Subtask check_file
[2022-09-05 09:54:12,362] {task_command.py:371} INFO - Running <TaskInstance: create_tables.check_file scheduled__2022-09-03T00:00:00+00:00 [running]> on host 613319c2eb0f
[2022-09-05 09:54:13,316] {taskinstance.py:1591} INFO - Exporting the following env vars:
AIRFLOW_CTX_DAG_OWNER=***
AIRFLOW_CTX_DAG_ID=create_tables
AIRFLOW_CTX_TASK_ID=check_file
AIRFLOW_CTX_EXECUTION_DATE=2022-09-03T00:00:00+00:00
AIRFLOW_CTX_TRY_NUMBER=8
AIRFLOW_CTX_DAG_RUN_ID=scheduled__2022-09-03T00:00:00+00:00
[2022-09-05 09:54:13,320] {subprocess.py:62} INFO - Tmp dir root location: 
 /tmp
[2022-09-05 09:54:13,330] {subprocess.py:74} INFO - Running command: ['bash', '-c', 'shasum ~/data/20181024_d1_0830_0900.csv']
[2022-09-05 09:54:13,372] {subprocess.py:85} INFO - Output:
[2022-09-05 09:54:13,540] {subprocess.py:92} INFO - shasum: /home/***/data/20181024_d1_0830_0900.csv: No such file or directory
[2022-09-05 09:54:13,564] {subprocess.py:96} INFO - Command exited with return code 1
[2022-09-05 09:54:13,680] {taskinstance.py:1909} ERROR - Task failed with exception
Traceback (most recent call last):
  File "/home/airflow/.local/lib/python3.7/site-packages/airflow/operators/bash.py", line 195, in execute
    f'Bash command failed. The command returned a non-zero exit code {result.exit_code}.'
airflow.exceptions.AirflowException: Bash command failed. The command returned a non-zero exit code 1.
[2022-09-05 09:54:13,710] {taskinstance.py:1420} INFO - Marking task as UP_FOR_RETRY. dag_id=create_tables, task_id=check_file, execution_date=20220903T000000, start_date=20220905T095411, end_date=20220905T095413
[2022-09-05 09:54:14,098] {standard_task_runner.py:97} ERROR - Failed to execute job 43 for task check_file (Bash command failed. The command returned a non-zero exit code 1.; 156)
[2022-09-05 09:54:14,139] {local_task_job.py:156} INFO - Task exited with return code 1
[2022-09-05 09:54:14,507] {local_task_job.py:273} INFO - 0 downstream tasks scheduled from follow-on schedule check
