[2022-09-05 14:26:29,811] {taskinstance.py:1179} INFO - Dependencies all met for <TaskInstance: create_tables.check_file scheduled__2022-09-03T00:00:00+00:00 [queued]>
[2022-09-05 14:26:29,854] {taskinstance.py:1179} INFO - Dependencies all met for <TaskInstance: create_tables.check_file scheduled__2022-09-03T00:00:00+00:00 [queued]>
[2022-09-05 14:26:29,855] {taskinstance.py:1376} INFO - 
--------------------------------------------------------------------------------
[2022-09-05 14:26:29,855] {taskinstance.py:1377} INFO - Starting attempt 22 of 24
[2022-09-05 14:26:29,856] {taskinstance.py:1378} INFO - 
--------------------------------------------------------------------------------
[2022-09-05 14:26:29,960] {taskinstance.py:1397} INFO - Executing <Task(BashOperator): check_file> on 2022-09-03 00:00:00+00:00
[2022-09-05 14:26:29,976] {standard_task_runner.py:52} INFO - Started process 910 to run task
[2022-09-05 14:26:29,993] {standard_task_runner.py:79} INFO - Running: ['***', 'tasks', 'run', 'create_tables', 'check_file', 'scheduled__2022-09-03T00:00:00+00:00', '--job-id', '120', '--raw', '--subdir', 'DAGS_FOLDER/create.py', '--cfg-path', '/tmp/tmp9wohah83', '--error-file', '/tmp/tmppf8houqs']
[2022-09-05 14:26:29,994] {standard_task_runner.py:80} INFO - Job 120: Subtask check_file
[2022-09-05 14:26:32,617] {task_command.py:371} INFO - Running <TaskInstance: create_tables.check_file scheduled__2022-09-03T00:00:00+00:00 [running]> on host cdeef4137858
[2022-09-05 14:26:33,686] {taskinstance.py:1591} INFO - Exporting the following env vars:
AIRFLOW_CTX_DAG_OWNER=***
AIRFLOW_CTX_DAG_ID=create_tables
AIRFLOW_CTX_TASK_ID=check_file
AIRFLOW_CTX_EXECUTION_DATE=2022-09-03T00:00:00+00:00
AIRFLOW_CTX_TRY_NUMBER=22
AIRFLOW_CTX_DAG_RUN_ID=scheduled__2022-09-03T00:00:00+00:00
[2022-09-05 14:26:33,955] {subprocess.py:62} INFO - Tmp dir root location: 
 /tmp
[2022-09-05 14:26:33,958] {subprocess.py:74} INFO - Running command: ['bash', '-c', 'shasum ~ /data/20181024_d1_0830_0900.csv']
[2022-09-05 14:26:34,020] {subprocess.py:85} INFO - Output:
[2022-09-05 14:26:34,104] {subprocess.py:92} INFO - shasum: /home/***: Is a directory
[2022-09-05 14:26:34,105] {subprocess.py:92} INFO - shasum: /data/20181024_d1_0830_0900.csv: No such file or directory
[2022-09-05 14:26:34,106] {subprocess.py:96} INFO - Command exited with return code 1
[2022-09-05 14:26:34,228] {taskinstance.py:1909} ERROR - Task failed with exception
Traceback (most recent call last):
  File "/home/airflow/.local/lib/python3.7/site-packages/airflow/operators/bash.py", line 195, in execute
    f'Bash command failed. The command returned a non-zero exit code {result.exit_code}.'
airflow.exceptions.AirflowException: Bash command failed. The command returned a non-zero exit code 1.
[2022-09-05 14:26:34,245] {taskinstance.py:1420} INFO - Marking task as UP_FOR_RETRY. dag_id=create_tables, task_id=check_file, execution_date=20220903T000000, start_date=20220905T142629, end_date=20220905T142634
[2022-09-05 14:26:34,642] {standard_task_runner.py:97} ERROR - Failed to execute job 120 for task check_file (Bash command failed. The command returned a non-zero exit code 1.; 910)
[2022-09-05 14:26:34,705] {local_task_job.py:156} INFO - Task exited with return code 1
[2022-09-05 14:26:35,182] {local_task_job.py:273} INFO - 0 downstream tasks scheduled from follow-on schedule check
