[2022-09-05 09:53:51,371] {taskinstance.py:1179} INFO - Dependencies all met for <TaskInstance: create_tables.check_file scheduled__2022-09-03T00:00:00+00:00 [queued]>
[2022-09-05 09:53:51,398] {taskinstance.py:1179} INFO - Dependencies all met for <TaskInstance: create_tables.check_file scheduled__2022-09-03T00:00:00+00:00 [queued]>
[2022-09-05 09:53:51,399] {taskinstance.py:1376} INFO - 
--------------------------------------------------------------------------------
[2022-09-05 09:53:51,400] {taskinstance.py:1377} INFO - Starting attempt 7 of 9
[2022-09-05 09:53:51,401] {taskinstance.py:1378} INFO - 
--------------------------------------------------------------------------------
[2022-09-05 09:53:51,487] {taskinstance.py:1397} INFO - Executing <Task(BashOperator): check_file> on 2022-09-03 00:00:00+00:00
[2022-09-05 09:53:51,495] {standard_task_runner.py:52} INFO - Started process 126 to run task
[2022-09-05 09:53:51,501] {standard_task_runner.py:79} INFO - Running: ['***', 'tasks', 'run', 'create_tables', 'check_file', 'scheduled__2022-09-03T00:00:00+00:00', '--job-id', '38', '--raw', '--subdir', 'DAGS_FOLDER/create.py', '--cfg-path', '/tmp/tmp7ai026ql', '--error-file', '/tmp/tmpowf6g7lt']
[2022-09-05 09:53:51,502] {standard_task_runner.py:80} INFO - Job 38: Subtask check_file
[2022-09-05 09:53:51,734] {task_command.py:371} INFO - Running <TaskInstance: create_tables.check_file scheduled__2022-09-03T00:00:00+00:00 [running]> on host 613319c2eb0f
[2022-09-05 09:53:52,240] {taskinstance.py:1591} INFO - Exporting the following env vars:
AIRFLOW_CTX_DAG_OWNER=***
AIRFLOW_CTX_DAG_ID=create_tables
AIRFLOW_CTX_TASK_ID=check_file
AIRFLOW_CTX_EXECUTION_DATE=2022-09-03T00:00:00+00:00
AIRFLOW_CTX_TRY_NUMBER=7
AIRFLOW_CTX_DAG_RUN_ID=scheduled__2022-09-03T00:00:00+00:00
[2022-09-05 09:53:52,259] {subprocess.py:62} INFO - Tmp dir root location: 
 /tmp
[2022-09-05 09:53:52,268] {subprocess.py:74} INFO - Running command: ['bash', '-c', 'shasum ~/data/20181024_d1_0830_0900.csv']
[2022-09-05 09:53:52,392] {subprocess.py:85} INFO - Output:
[2022-09-05 09:53:52,498] {subprocess.py:92} INFO - shasum: /home/***/data/20181024_d1_0830_0900.csv: No such file or directory
[2022-09-05 09:53:52,499] {subprocess.py:96} INFO - Command exited with return code 1
[2022-09-05 09:53:52,571] {taskinstance.py:1909} ERROR - Task failed with exception
Traceback (most recent call last):
  File "/home/airflow/.local/lib/python3.7/site-packages/airflow/operators/bash.py", line 195, in execute
    f'Bash command failed. The command returned a non-zero exit code {result.exit_code}.'
airflow.exceptions.AirflowException: Bash command failed. The command returned a non-zero exit code 1.
[2022-09-05 09:53:52,588] {taskinstance.py:1420} INFO - Marking task as UP_FOR_RETRY. dag_id=create_tables, task_id=check_file, execution_date=20220903T000000, start_date=20220905T095351, end_date=20220905T095352
[2022-09-05 09:53:52,708] {standard_task_runner.py:97} ERROR - Failed to execute job 38 for task check_file (Bash command failed. The command returned a non-zero exit code 1.; 126)
[2022-09-05 09:53:52,768] {local_task_job.py:156} INFO - Task exited with return code 1
[2022-09-05 09:53:52,931] {local_task_job.py:273} INFO - 0 downstream tasks scheduled from follow-on schedule check
