[2022-09-05 10:12:53,835] {taskinstance.py:1179} INFO - Dependencies all met for <TaskInstance: create_tables.check_file scheduled__2022-09-03T00:00:00+00:00 [queued]>
[2022-09-05 10:12:53,860] {taskinstance.py:1179} INFO - Dependencies all met for <TaskInstance: create_tables.check_file scheduled__2022-09-03T00:00:00+00:00 [queued]>
[2022-09-05 10:12:53,861] {taskinstance.py:1376} INFO - 
--------------------------------------------------------------------------------
[2022-09-05 10:12:53,861] {taskinstance.py:1377} INFO - Starting attempt 21 of 21
[2022-09-05 10:12:53,863] {taskinstance.py:1378} INFO - 
--------------------------------------------------------------------------------
[2022-09-05 10:12:53,938] {taskinstance.py:1397} INFO - Executing <Task(BashOperator): check_file> on 2022-09-03 00:00:00+00:00
[2022-09-05 10:12:53,944] {standard_task_runner.py:52} INFO - Started process 966 to run task
[2022-09-05 10:12:53,950] {standard_task_runner.py:79} INFO - Running: ['***', 'tasks', 'run', 'create_tables', 'check_file', 'scheduled__2022-09-03T00:00:00+00:00', '--job-id', '111', '--raw', '--subdir', 'DAGS_FOLDER/create.py', '--cfg-path', '/tmp/tmpe28iaxcv', '--error-file', '/tmp/tmpj8rkgg9z']
[2022-09-05 10:12:53,951] {standard_task_runner.py:80} INFO - Job 111: Subtask check_file
[2022-09-05 10:12:54,124] {task_command.py:371} INFO - Running <TaskInstance: create_tables.check_file scheduled__2022-09-03T00:00:00+00:00 [running]> on host 613319c2eb0f
[2022-09-05 10:12:54,464] {taskinstance.py:1591} INFO - Exporting the following env vars:
AIRFLOW_CTX_DAG_OWNER=***
AIRFLOW_CTX_DAG_ID=create_tables
AIRFLOW_CTX_TASK_ID=check_file
AIRFLOW_CTX_EXECUTION_DATE=2022-09-03T00:00:00+00:00
AIRFLOW_CTX_TRY_NUMBER=21
AIRFLOW_CTX_DAG_RUN_ID=scheduled__2022-09-03T00:00:00+00:00
[2022-09-05 10:12:54,467] {subprocess.py:62} INFO - Tmp dir root location: 
 /tmp
[2022-09-05 10:12:54,468] {subprocess.py:74} INFO - Running command: ['bash', '-c', 'shasum ~ /data/20181024_d1_0830_0900.csv']
[2022-09-05 10:12:54,484] {subprocess.py:85} INFO - Output:
[2022-09-05 10:12:54,541] {subprocess.py:92} INFO - shasum: /home/***: Is a directory
[2022-09-05 10:12:54,541] {subprocess.py:92} INFO - shasum: /data/20181024_d1_0830_0900.csv: No such file or directory
[2022-09-05 10:12:54,542] {subprocess.py:96} INFO - Command exited with return code 1
[2022-09-05 10:12:54,573] {taskinstance.py:1909} ERROR - Task failed with exception
Traceback (most recent call last):
  File "/home/airflow/.local/lib/python3.7/site-packages/airflow/operators/bash.py", line 195, in execute
    f'Bash command failed. The command returned a non-zero exit code {result.exit_code}.'
airflow.exceptions.AirflowException: Bash command failed. The command returned a non-zero exit code 1.
[2022-09-05 10:12:54,583] {taskinstance.py:1420} INFO - Marking task as FAILED. dag_id=create_tables, task_id=check_file, execution_date=20220903T000000, start_date=20220905T101253, end_date=20220905T101254
[2022-09-05 10:12:54,639] {standard_task_runner.py:97} ERROR - Failed to execute job 111 for task check_file (Bash command failed. The command returned a non-zero exit code 1.; 966)
[2022-09-05 10:12:54,686] {local_task_job.py:156} INFO - Task exited with return code 1
[2022-09-05 10:12:55,807] {local_task_job.py:273} INFO - 0 downstream tasks scheduled from follow-on schedule check
