[2022-09-05 09:23:57,842] {taskinstance.py:1179} INFO - Dependencies all met for <TaskInstance: create_tables.check_file scheduled__2022-09-03T00:00:00+00:00 [queued]>
[2022-09-05 09:23:58,072] {taskinstance.py:1179} INFO - Dependencies all met for <TaskInstance: create_tables.check_file scheduled__2022-09-03T00:00:00+00:00 [queued]>
[2022-09-05 09:23:58,082] {taskinstance.py:1376} INFO - 
--------------------------------------------------------------------------------
[2022-09-05 09:23:58,083] {taskinstance.py:1377} INFO - Starting attempt 1 of 3
[2022-09-05 09:23:58,166] {taskinstance.py:1378} INFO - 
--------------------------------------------------------------------------------
[2022-09-05 09:23:58,521] {taskinstance.py:1397} INFO - Executing <Task(BashOperator): check_file> on 2022-09-03 00:00:00+00:00
[2022-09-05 09:23:58,538] {standard_task_runner.py:52} INFO - Started process 642 to run task
[2022-09-05 09:23:58,558] {standard_task_runner.py:79} INFO - Running: ['***', 'tasks', 'run', 'create_tables', 'check_file', 'scheduled__2022-09-03T00:00:00+00:00', '--job-id', '8', '--raw', '--subdir', 'DAGS_FOLDER/create.py', '--cfg-path', '/tmp/tmptpu41xxu', '--error-file', '/tmp/tmptnp6supp']
[2022-09-05 09:23:58,565] {standard_task_runner.py:80} INFO - Job 8: Subtask check_file
[2022-09-05 09:23:59,011] {task_command.py:371} INFO - Running <TaskInstance: create_tables.check_file scheduled__2022-09-03T00:00:00+00:00 [running]> on host bcd27e6a9f6c
[2022-09-05 09:24:00,031] {taskinstance.py:1591} INFO - Exporting the following env vars:
AIRFLOW_CTX_DAG_OWNER=***
AIRFLOW_CTX_DAG_ID=create_tables
AIRFLOW_CTX_TASK_ID=check_file
AIRFLOW_CTX_EXECUTION_DATE=2022-09-03T00:00:00+00:00
AIRFLOW_CTX_TRY_NUMBER=1
AIRFLOW_CTX_DAG_RUN_ID=scheduled__2022-09-03T00:00:00+00:00
[2022-09-05 09:24:00,036] {subprocess.py:62} INFO - Tmp dir root location: 
 /tmp
[2022-09-05 09:24:00,045] {subprocess.py:74} INFO - Running command: ['bash', '-c', 'shasum~/data/20181024_d1_0830_0900.csv']
[2022-09-05 09:24:00,115] {subprocess.py:85} INFO - Output:
[2022-09-05 09:24:00,145] {subprocess.py:92} INFO - bash: line 1: shasum~/data/20181024_d1_0830_0900.csv: No such file or directory
[2022-09-05 09:24:00,204] {subprocess.py:96} INFO - Command exited with return code 127
[2022-09-05 09:24:00,382] {taskinstance.py:1909} ERROR - Task failed with exception
Traceback (most recent call last):
  File "/home/airflow/.local/lib/python3.7/site-packages/airflow/operators/bash.py", line 195, in execute
    f'Bash command failed. The command returned a non-zero exit code {result.exit_code}.'
airflow.exceptions.AirflowException: Bash command failed. The command returned a non-zero exit code 127.
[2022-09-05 09:24:00,403] {taskinstance.py:1420} INFO - Marking task as UP_FOR_RETRY. dag_id=create_tables, task_id=check_file, execution_date=20220903T000000, start_date=20220905T092357, end_date=20220905T092400
[2022-09-05 09:24:00,886] {standard_task_runner.py:97} ERROR - Failed to execute job 8 for task check_file (Bash command failed. The command returned a non-zero exit code 127.; 642)
[2022-09-05 09:24:00,963] {local_task_job.py:156} INFO - Task exited with return code 1
[2022-09-05 09:24:02,140] {local_task_job.py:273} INFO - 0 downstream tasks scheduled from follow-on schedule check
