[2022-09-05 09:54:33,598] {taskinstance.py:1179} INFO - Dependencies all met for <TaskInstance: create_tables.check_file scheduled__2022-09-03T00:00:00+00:00 [queued]>
[2022-09-05 09:54:33,627] {taskinstance.py:1179} INFO - Dependencies all met for <TaskInstance: create_tables.check_file scheduled__2022-09-03T00:00:00+00:00 [queued]>
[2022-09-05 09:54:33,629] {taskinstance.py:1376} INFO - 
--------------------------------------------------------------------------------
[2022-09-05 09:54:33,633] {taskinstance.py:1377} INFO - Starting attempt 9 of 9
[2022-09-05 09:54:33,645] {taskinstance.py:1378} INFO - 
--------------------------------------------------------------------------------
[2022-09-05 09:54:33,772] {taskinstance.py:1397} INFO - Executing <Task(BashOperator): check_file> on 2022-09-03 00:00:00+00:00
[2022-09-05 09:54:33,778] {standard_task_runner.py:52} INFO - Started process 186 to run task
[2022-09-05 09:54:33,786] {standard_task_runner.py:79} INFO - Running: ['***', 'tasks', 'run', 'create_tables', 'check_file', 'scheduled__2022-09-03T00:00:00+00:00', '--job-id', '50', '--raw', '--subdir', 'DAGS_FOLDER/create.py', '--cfg-path', '/tmp/tmpe850n5xn', '--error-file', '/tmp/tmpsd16y94o']
[2022-09-05 09:54:33,787] {standard_task_runner.py:80} INFO - Job 50: Subtask check_file
[2022-09-05 09:54:34,141] {task_command.py:371} INFO - Running <TaskInstance: create_tables.check_file scheduled__2022-09-03T00:00:00+00:00 [running]> on host 613319c2eb0f
[2022-09-05 09:54:34,683] {taskinstance.py:1591} INFO - Exporting the following env vars:
AIRFLOW_CTX_DAG_OWNER=***
AIRFLOW_CTX_DAG_ID=create_tables
AIRFLOW_CTX_TASK_ID=check_file
AIRFLOW_CTX_EXECUTION_DATE=2022-09-03T00:00:00+00:00
AIRFLOW_CTX_TRY_NUMBER=9
AIRFLOW_CTX_DAG_RUN_ID=scheduled__2022-09-03T00:00:00+00:00
[2022-09-05 09:54:34,685] {subprocess.py:62} INFO - Tmp dir root location: 
 /tmp
[2022-09-05 09:54:34,688] {subprocess.py:74} INFO - Running command: ['bash', '-c', 'shasum ~/data/20181024_d1_0830_0900.csv']
[2022-09-05 09:54:34,784] {subprocess.py:85} INFO - Output:
[2022-09-05 09:54:34,861] {subprocess.py:92} INFO - shasum: /home/***/data/20181024_d1_0830_0900.csv: No such file or directory
[2022-09-05 09:54:34,863] {subprocess.py:96} INFO - Command exited with return code 1
[2022-09-05 09:54:34,905] {taskinstance.py:1909} ERROR - Task failed with exception
Traceback (most recent call last):
  File "/home/airflow/.local/lib/python3.7/site-packages/airflow/operators/bash.py", line 195, in execute
    f'Bash command failed. The command returned a non-zero exit code {result.exit_code}.'
airflow.exceptions.AirflowException: Bash command failed. The command returned a non-zero exit code 1.
[2022-09-05 09:54:34,914] {taskinstance.py:1420} INFO - Marking task as FAILED. dag_id=create_tables, task_id=check_file, execution_date=20220903T000000, start_date=20220905T095433, end_date=20220905T095434
[2022-09-05 09:54:35,076] {standard_task_runner.py:97} ERROR - Failed to execute job 50 for task check_file (Bash command failed. The command returned a non-zero exit code 1.; 186)
[2022-09-05 09:54:35,117] {local_task_job.py:156} INFO - Task exited with return code 1
[2022-09-05 09:54:35,320] {local_task_job.py:273} INFO - 0 downstream tasks scheduled from follow-on schedule check
