[2022-09-05 10:10:44,854] {taskinstance.py:1179} INFO - Dependencies all met for <TaskInstance: create_tables.check_file scheduled__2022-09-03T00:00:00+00:00 [queued]>
[2022-09-05 10:10:44,887] {taskinstance.py:1179} INFO - Dependencies all met for <TaskInstance: create_tables.check_file scheduled__2022-09-03T00:00:00+00:00 [queued]>
[2022-09-05 10:10:44,888] {taskinstance.py:1376} INFO - 
--------------------------------------------------------------------------------
[2022-09-05 10:10:44,888] {taskinstance.py:1377} INFO - Starting attempt 17 of 18
[2022-09-05 10:10:44,927] {taskinstance.py:1378} INFO - 
--------------------------------------------------------------------------------
[2022-09-05 10:10:45,049] {taskinstance.py:1397} INFO - Executing <Task(BashOperator): check_file> on 2022-09-03 00:00:00+00:00
[2022-09-05 10:10:45,070] {standard_task_runner.py:52} INFO - Started process 856 to run task
[2022-09-05 10:10:45,086] {standard_task_runner.py:79} INFO - Running: ['***', 'tasks', 'run', 'create_tables', 'check_file', 'scheduled__2022-09-03T00:00:00+00:00', '--job-id', '95', '--raw', '--subdir', 'DAGS_FOLDER/create.py', '--cfg-path', '/tmp/tmpiotlcx33', '--error-file', '/tmp/tmp7m4r786p']
[2022-09-05 10:10:45,087] {standard_task_runner.py:80} INFO - Job 95: Subtask check_file
[2022-09-05 10:10:45,430] {task_command.py:371} INFO - Running <TaskInstance: create_tables.check_file scheduled__2022-09-03T00:00:00+00:00 [running]> on host 613319c2eb0f
[2022-09-05 10:10:45,896] {taskinstance.py:1591} INFO - Exporting the following env vars:
AIRFLOW_CTX_DAG_OWNER=***
AIRFLOW_CTX_DAG_ID=create_tables
AIRFLOW_CTX_TASK_ID=check_file
AIRFLOW_CTX_EXECUTION_DATE=2022-09-03T00:00:00+00:00
AIRFLOW_CTX_TRY_NUMBER=17
AIRFLOW_CTX_DAG_RUN_ID=scheduled__2022-09-03T00:00:00+00:00
[2022-09-05 10:10:45,901] {subprocess.py:62} INFO - Tmp dir root location: 
 /tmp
[2022-09-05 10:10:45,911] {subprocess.py:74} INFO - Running command: ['bash', '-c', ' ~ /data/20181024_d1_0830_0900.csv']
[2022-09-05 10:10:45,935] {subprocess.py:85} INFO - Output:
[2022-09-05 10:10:45,939] {subprocess.py:92} INFO - bash: line 1: /home/***: Is a directory
[2022-09-05 10:10:45,944] {subprocess.py:96} INFO - Command exited with return code 126
[2022-09-05 10:10:46,040] {taskinstance.py:1909} ERROR - Task failed with exception
Traceback (most recent call last):
  File "/home/airflow/.local/lib/python3.7/site-packages/airflow/operators/bash.py", line 195, in execute
    f'Bash command failed. The command returned a non-zero exit code {result.exit_code}.'
airflow.exceptions.AirflowException: Bash command failed. The command returned a non-zero exit code 126.
[2022-09-05 10:10:46,062] {taskinstance.py:1420} INFO - Marking task as UP_FOR_RETRY. dag_id=create_tables, task_id=check_file, execution_date=20220903T000000, start_date=20220905T101044, end_date=20220905T101046
[2022-09-05 10:10:46,140] {standard_task_runner.py:97} ERROR - Failed to execute job 95 for task check_file (Bash command failed. The command returned a non-zero exit code 126.; 856)
[2022-09-05 10:10:46,193] {local_task_job.py:156} INFO - Task exited with return code 1
[2022-09-05 10:10:46,393] {local_task_job.py:273} INFO - 0 downstream tasks scheduled from follow-on schedule check
