[2022-09-05 09:29:42,441] {taskinstance.py:1179} INFO - Dependencies all met for <TaskInstance: create_tables.check_file scheduled__2022-09-03T00:00:00+00:00 [queued]>
[2022-09-05 09:29:42,507] {taskinstance.py:1179} INFO - Dependencies all met for <TaskInstance: create_tables.check_file scheduled__2022-09-03T00:00:00+00:00 [queued]>
[2022-09-05 09:29:42,514] {taskinstance.py:1376} INFO - 
--------------------------------------------------------------------------------
[2022-09-05 09:29:42,519] {taskinstance.py:1377} INFO - Starting attempt 6 of 6
[2022-09-05 09:29:42,530] {taskinstance.py:1378} INFO - 
--------------------------------------------------------------------------------
[2022-09-05 09:29:42,726] {taskinstance.py:1397} INFO - Executing <Task(BashOperator): check_file> on 2022-09-03 00:00:00+00:00
[2022-09-05 09:29:42,733] {standard_task_runner.py:52} INFO - Started process 888 to run task
[2022-09-05 09:29:42,740] {standard_task_runner.py:79} INFO - Running: ['***', 'tasks', 'run', 'create_tables', 'check_file', 'scheduled__2022-09-03T00:00:00+00:00', '--job-id', '33', '--raw', '--subdir', 'DAGS_FOLDER/create.py', '--cfg-path', '/tmp/tmpsy_pmf3e', '--error-file', '/tmp/tmp37856zy0']
[2022-09-05 09:29:42,742] {standard_task_runner.py:80} INFO - Job 33: Subtask check_file
[2022-09-05 09:29:43,093] {task_command.py:371} INFO - Running <TaskInstance: create_tables.check_file scheduled__2022-09-03T00:00:00+00:00 [running]> on host bcd27e6a9f6c
[2022-09-05 09:29:43,399] {taskinstance.py:1591} INFO - Exporting the following env vars:
AIRFLOW_CTX_DAG_OWNER=***
AIRFLOW_CTX_DAG_ID=create_tables
AIRFLOW_CTX_TASK_ID=check_file
AIRFLOW_CTX_EXECUTION_DATE=2022-09-03T00:00:00+00:00
AIRFLOW_CTX_TRY_NUMBER=6
AIRFLOW_CTX_DAG_RUN_ID=scheduled__2022-09-03T00:00:00+00:00
[2022-09-05 09:29:43,401] {subprocess.py:62} INFO - Tmp dir root location: 
 /tmp
[2022-09-05 09:29:43,414] {subprocess.py:74} INFO - Running command: ['bash', '-c', 'shasum~/data/20181024_d1_0830_0900.csv']
[2022-09-05 09:29:43,432] {subprocess.py:85} INFO - Output:
[2022-09-05 09:29:43,437] {subprocess.py:92} INFO - bash: line 1: shasum~/data/20181024_d1_0830_0900.csv: No such file or directory
[2022-09-05 09:29:43,438] {subprocess.py:96} INFO - Command exited with return code 127
[2022-09-05 09:29:43,472] {taskinstance.py:1909} ERROR - Task failed with exception
Traceback (most recent call last):
  File "/home/airflow/.local/lib/python3.7/site-packages/airflow/operators/bash.py", line 195, in execute
    f'Bash command failed. The command returned a non-zero exit code {result.exit_code}.'
airflow.exceptions.AirflowException: Bash command failed. The command returned a non-zero exit code 127.
[2022-09-05 09:29:43,483] {taskinstance.py:1420} INFO - Marking task as FAILED. dag_id=create_tables, task_id=check_file, execution_date=20220903T000000, start_date=20220905T092942, end_date=20220905T092943
[2022-09-05 09:29:43,638] {standard_task_runner.py:97} ERROR - Failed to execute job 33 for task check_file (Bash command failed. The command returned a non-zero exit code 127.; 888)
[2022-09-05 09:29:43,680] {local_task_job.py:156} INFO - Task exited with return code 1
[2022-09-05 09:29:43,869] {local_task_job.py:273} INFO - 0 downstream tasks scheduled from follow-on schedule check
